ERROR - 11-Jan-24 16:55:51 - Internal Server Error: /recommend_courses
Traceback (most recent call last):
  File "C:\Users\Simon\AppData\Roaming\Python\Python311\site-packages\django\core\handlers\exception.py", line 55, in inner
    response = get_response(request)
               ^^^^^^^^^^^^^^^^^^^^^
  File "C:\Users\Simon\AppData\Roaming\Python\Python311\site-packages\django\core\handlers\base.py", line 197, in _get_response
    response = wrapped_callback(request, *callback_args, **callback_kwargs)
               ^^^^^^^^^^^^^^^^^^^^^^^^^^^^^^^^^^^^^^^^^^^^^^^^^^^^^^^^^^^^
  File "C:\Users\Simon\proacted\AIacademia\academia_app\views.py", line 225, in recommend_courses
    recommendations = load_model(user_subjects_done, user_interests)
                      ^^^^^^^^^^^^^^^^^^^^^^^^^^^^^^^^^^^^^^^^^^^^^^
  File "C:\Users\Simon\proacted\AIacademia\python_scripts\recommender_clustering_pooling.py", line 85, in load_model
    objectives_tfidf_matrix = objectives_vectorizer.fit_transform(df['Course Objectives'])
                                                                  ~~^^^^^^^^^^^^^^^^^^^^^
  File "C:\Users\Simon\AppData\Roaming\Python\Python311\site-packages\pandas\core\frame.py", line 3896, in __getitem__
    indexer = self.columns.get_loc(key)
              ^^^^^^^^^^^^^^^^^^^^^^^^^
  File "C:\Users\Simon\AppData\Roaming\Python\Python311\site-packages\pandas\core\indexes\range.py", line 418, in get_loc
    raise KeyError(key)
KeyError: 'Course Objectives'
INFO - 11-Jan-24 16:57:20 - C:\Users\Simon\proacted\AIacademia\academia_app\urls.py changed, reloading.
INFO - 11-Jan-24 17:03:45 - C:\Users\Simon\proacted\AIacademia\academia_app\views.py changed, reloading.
INFO - 11-Jan-24 17:15:55 - C:\Users\Simon\proacted\AIacademia\academia_app\urls.py changed, reloading.
INFO - 11-Jan-24 17:16:16 - C:\Users\Simon\proacted\AIacademia\academia_app\views.py changed, reloading.
INFO - 11-Jan-24 17:16:42 - C:\Users\Simon\proacted\AIacademia\academia_app\views.py changed, reloading.
ERROR - 11-Jan-24 17:23:29 - Internal Server Error: /recommend_courses
Traceback (most recent call last):
  File "C:\Users\Simon\AppData\Roaming\Python\Python311\site-packages\django\core\handlers\exception.py", line 55, in inner
    response = get_response(request)
               ^^^^^^^^^^^^^^^^^^^^^
  File "C:\Users\Simon\AppData\Roaming\Python\Python311\site-packages\django\core\handlers\base.py", line 197, in _get_response
    response = wrapped_callback(request, *callback_args, **callback_kwargs)
               ^^^^^^^^^^^^^^^^^^^^^^^^^^^^^^^^^^^^^^^^^^^^^^^^^^^^^^^^^^^^
  File "C:\Users\Simon\proacted\AIacademia\academia_app\views.py", line 226, in recommend_courses
    recommendations = load_model(user_subjects_done, user_interests)
                      ^^^^^^^^^^^^^^^^^^^^^^^^^^^^^^^^^^^^^^^^^^^^^^
  File "C:\Users\Simon\proacted\AIacademia\python_scripts\recommender_clustering_pooling.py", line 85, in load_model
    objectives_tfidf_matrix = objectives_vectorizer.fit_transform(df['Course Objectives'])
                                                                  ~~^^^^^^^^^^^^^^^^^^^^^
  File "C:\Users\Simon\AppData\Roaming\Python\Python311\site-packages\pandas\core\frame.py", line 3896, in __getitem__
    indexer = self.columns.get_loc(key)
              ^^^^^^^^^^^^^^^^^^^^^^^^^
  File "C:\Users\Simon\AppData\Roaming\Python\Python311\site-packages\pandas\core\indexes\range.py", line 418, in get_loc
    raise KeyError(key)
KeyError: 'Course Objectives'
ERROR - 11-Jan-24 17:23:38 - Internal Server Error: /recommend_courses
Traceback (most recent call last):
  File "C:\Users\Simon\AppData\Roaming\Python\Python311\site-packages\django\core\handlers\exception.py", line 55, in inner
    response = get_response(request)
               ^^^^^^^^^^^^^^^^^^^^^
  File "C:\Users\Simon\AppData\Roaming\Python\Python311\site-packages\django\core\handlers\base.py", line 197, in _get_response
    response = wrapped_callback(request, *callback_args, **callback_kwargs)
               ^^^^^^^^^^^^^^^^^^^^^^^^^^^^^^^^^^^^^^^^^^^^^^^^^^^^^^^^^^^^
  File "C:\Users\Simon\proacted\AIacademia\academia_app\views.py", line 226, in recommend_courses
    recommendations = load_model(user_subjects_done, user_interests)
                      ^^^^^^^^^^^^^^^^^^^^^^^^^^^^^^^^^^^^^^^^^^^^^^
  File "C:\Users\Simon\proacted\AIacademia\python_scripts\recommender_clustering_pooling.py", line 85, in load_model
    objectives_tfidf_matrix = objectives_vectorizer.fit_transform(df['Course Objectives'])
                                                                  ~~^^^^^^^^^^^^^^^^^^^^^
  File "C:\Users\Simon\AppData\Roaming\Python\Python311\site-packages\pandas\core\frame.py", line 3896, in __getitem__
    indexer = self.columns.get_loc(key)
              ^^^^^^^^^^^^^^^^^^^^^^^^^
  File "C:\Users\Simon\AppData\Roaming\Python\Python311\site-packages\pandas\core\indexes\range.py", line 418, in get_loc
    raise KeyError(key)
KeyError: 'Course Objectives'
WARNING - 12-Jan-24 11:49:57 - Not Found: /favicon.ico
ERROR - 12-Jan-24 11:50:13 - Internal Server Error: /recommend_courses
Traceback (most recent call last):
  File "C:\Users\Simon\AppData\Roaming\Python\Python311\site-packages\django\core\handlers\exception.py", line 55, in inner
    response = get_response(request)
               ^^^^^^^^^^^^^^^^^^^^^
  File "C:\Users\Simon\AppData\Roaming\Python\Python311\site-packages\django\core\handlers\base.py", line 204, in _get_response
    self.check_response(response, callback)
  File "C:\Users\Simon\AppData\Roaming\Python\Python311\site-packages\django\core\handlers\base.py", line 332, in check_response
    raise ValueError(
ValueError: The view academia_app.views.recommend_courses didn't return an HttpResponse object. It returned None instead.
INFO - 12-Jan-24 11:51:48 - C:\Users\Simon\proacted\AIacademia\academia_app\views.py changed, reloading.
ERROR - 12-Jan-24 11:58:42 - Internal Server Error: /recommend_courses
Traceback (most recent call last):
  File "C:\Users\Simon\AppData\Roaming\Python\Python311\site-packages\django\core\handlers\exception.py", line 55, in inner
    response = get_response(request)
               ^^^^^^^^^^^^^^^^^^^^^
  File "C:\Users\Simon\AppData\Roaming\Python\Python311\site-packages\django\core\handlers\base.py", line 204, in _get_response
    self.check_response(response, callback)
  File "C:\Users\Simon\AppData\Roaming\Python\Python311\site-packages\django\core\handlers\base.py", line 332, in check_response
    raise ValueError(
ValueError: The view academia_app.views.recommend_courses didn't return an HttpResponse object. It returned None instead.
INFO - 12-Jan-24 12:00:32 - C:\Users\Simon\proacted\AIacademia\academia_app\views.py changed, reloading.
ERROR - 12-Jan-24 12:00:39 - Internal Server Error: /recommend_courses
Traceback (most recent call last):
  File "C:\Users\Simon\AppData\Roaming\Python\Python311\site-packages\django\core\handlers\exception.py", line 55, in inner
    response = get_response(request)
               ^^^^^^^^^^^^^^^^^^^^^
  File "C:\Users\Simon\AppData\Roaming\Python\Python311\site-packages\django\core\handlers\base.py", line 204, in _get_response
    self.check_response(response, callback)
  File "C:\Users\Simon\AppData\Roaming\Python\Python311\site-packages\django\core\handlers\base.py", line 332, in check_response
    raise ValueError(
ValueError: The view academia_app.views.recommend_courses didn't return an HttpResponse object. It returned None instead.
ERROR - 12-Jan-24 12:08:57 - Internal Server Error: /recommend_courses
Traceback (most recent call last):
  File "C:\Users\Simon\AppData\Roaming\Python\Python311\site-packages\django\core\handlers\exception.py", line 55, in inner
    response = get_response(request)
               ^^^^^^^^^^^^^^^^^^^^^
  File "C:\Users\Simon\AppData\Roaming\Python\Python311\site-packages\django\core\handlers\base.py", line 204, in _get_response
    self.check_response(response, callback)
  File "C:\Users\Simon\AppData\Roaming\Python\Python311\site-packages\django\core\handlers\base.py", line 332, in check_response
    raise ValueError(
ValueError: The view academia_app.views.recommend_courses didn't return an HttpResponse object. It returned None instead.
ERROR - 12-Jan-24 12:11:18 - Internal Server Error: /recommend_courses
Traceback (most recent call last):
  File "C:\Users\Simon\AppData\Roaming\Python\Python311\site-packages\django\core\handlers\exception.py", line 55, in inner
    response = get_response(request)
               ^^^^^^^^^^^^^^^^^^^^^
  File "C:\Users\Simon\AppData\Roaming\Python\Python311\site-packages\django\core\handlers\base.py", line 204, in _get_response
    self.check_response(response, callback)
  File "C:\Users\Simon\AppData\Roaming\Python\Python311\site-packages\django\core\handlers\base.py", line 332, in check_response
    raise ValueError(
ValueError: The view academia_app.views.recommend_courses didn't return an HttpResponse object. It returned None instead.
INFO - 12-Jan-24 12:16:05 - C:\Users\Simon\proacted\AIacademia\academia_app\views.py changed, reloading.
ERROR - 12-Jan-24 12:16:35 - Internal Server Error: /recommend_courses
Traceback (most recent call last):
  File "C:\Users\Simon\AppData\Roaming\Python\Python311\site-packages\django\core\handlers\exception.py", line 55, in inner
    response = get_response(request)
               ^^^^^^^^^^^^^^^^^^^^^
  File "C:\Users\Simon\AppData\Roaming\Python\Python311\site-packages\django\core\handlers\base.py", line 204, in _get_response
    self.check_response(response, callback)
  File "C:\Users\Simon\AppData\Roaming\Python\Python311\site-packages\django\core\handlers\base.py", line 332, in check_response
    raise ValueError(
ValueError: The view academia_app.views.recommend_courses didn't return an HttpResponse object. It returned None instead.
ERROR - 12-Jan-24 12:20:37 - Internal Server Error: /recommend_courses
Traceback (most recent call last):
  File "C:\Users\Simon\AppData\Roaming\Python\Python311\site-packages\django\core\handlers\exception.py", line 55, in inner
    response = get_response(request)
               ^^^^^^^^^^^^^^^^^^^^^
  File "C:\Users\Simon\AppData\Roaming\Python\Python311\site-packages\django\core\handlers\base.py", line 204, in _get_response
    self.check_response(response, callback)
  File "C:\Users\Simon\AppData\Roaming\Python\Python311\site-packages\django\core\handlers\base.py", line 332, in check_response
    raise ValueError(
ValueError: The view academia_app.views.recommend_courses didn't return an HttpResponse object. It returned None instead.
ERROR - 12-Jan-24 12:22:48 - Internal Server Error: /recommend_courses
Traceback (most recent call last):
  File "C:\Users\Simon\AppData\Roaming\Python\Python311\site-packages\django\core\handlers\exception.py", line 55, in inner
    response = get_response(request)
               ^^^^^^^^^^^^^^^^^^^^^
  File "C:\Users\Simon\AppData\Roaming\Python\Python311\site-packages\django\core\handlers\base.py", line 197, in _get_response
    response = wrapped_callback(request, *callback_args, **callback_kwargs)
               ^^^^^^^^^^^^^^^^^^^^^^^^^^^^^^^^^^^^^^^^^^^^^^^^^^^^^^^^^^^^
  File "C:\Users\Simon\proacted\AIacademia\academia_app\views.py", line 230, in recommend_courses
    recommendations = load_model(user_subjects_done, user_interests)
                      ^^^^^^^^^^^^^^^^^^^^^^^^^^^^^^^^^^^^^^^^^^^^^^
  File "C:\Users\Simon\proacted\AIacademia\python_scripts\recommender_clustering_pooling.py", line 245, in load_model
    vectorized_user_interests = clustered_weighted_vector(user_interests, model, objectives_vectorizer)
                                ^^^^^^^^^^^^^^^^^^^^^^^^^^^^^^^^^^^^^^^^^^^^^^^^^^^^^^^^^^^^^^^^^^^^^^^
  File "C:\Users\Simon\proacted\AIacademia\python_scripts\recommender_clustering_pooling.py", line 221, in clustered_weighted_vector
    kmeans.fit(word_vectors)
  File "C:\Users\Simon\AppData\Roaming\Python\Python311\site-packages\sklearn\base.py", line 1152, in wrapper
    return fit_method(estimator, *args, **kwargs)
           ^^^^^^^^^^^^^^^^^^^^^^^^^^^^^^^^^^^^^^
  File "C:\Users\Simon\AppData\Roaming\Python\Python311\site-packages\sklearn\cluster\_kmeans.py", line 1484, in fit
    self._check_params_vs_input(X)
  File "C:\Users\Simon\AppData\Roaming\Python\Python311\site-packages\sklearn\cluster\_kmeans.py", line 1416, in _check_params_vs_input
    super()._check_params_vs_input(X, default_n_init=10)
  File "C:\Users\Simon\AppData\Roaming\Python\Python311\site-packages\sklearn\cluster\_kmeans.py", line 866, in _check_params_vs_input
    raise ValueError(
ValueError: n_samples=6 should be >= n_clusters=7.
INFO - 12-Jan-24 12:24:00 - C:\Users\Simon\proacted\AIacademia\python_scripts\recommender_clustering_pooling.py changed, reloading.
ERROR - 12-Jan-24 12:25:03 - Internal Server Error: /recommend_courses
Traceback (most recent call last):
  File "C:\Users\Simon\AppData\Roaming\Python\Python311\site-packages\django\core\handlers\exception.py", line 55, in inner
    response = get_response(request)
               ^^^^^^^^^^^^^^^^^^^^^
  File "C:\Users\Simon\AppData\Roaming\Python\Python311\site-packages\django\core\handlers\base.py", line 197, in _get_response
    response = wrapped_callback(request, *callback_args, **callback_kwargs)
               ^^^^^^^^^^^^^^^^^^^^^^^^^^^^^^^^^^^^^^^^^^^^^^^^^^^^^^^^^^^^
  File "C:\Users\Simon\proacted\AIacademia\academia_app\views.py", line 234, in recommend_courses
    return render(request, 'recommended_courses.html', context)
           ^^^^^^^^^^^^^^^^^^^^^^^^^^^^^^^^^^^^^^^^^^^^^^^^^^^^
  File "C:\Users\Simon\AppData\Roaming\Python\Python311\site-packages\django\shortcuts.py", line 24, in render
    content = loader.render_to_string(template_name, context, request, using=using)
              ^^^^^^^^^^^^^^^^^^^^^^^^^^^^^^^^^^^^^^^^^^^^^^^^^^^^^^^^^^^^^^^^^^^^^
  File "C:\Users\Simon\AppData\Roaming\Python\Python311\site-packages\django\template\loader.py", line 61, in render_to_string
    template = get_template(template_name, using=using)
               ^^^^^^^^^^^^^^^^^^^^^^^^^^^^^^^^^^^^^^^^
  File "C:\Users\Simon\AppData\Roaming\Python\Python311\site-packages\django\template\loader.py", line 19, in get_template
    raise TemplateDoesNotExist(template_name, chain=chain)
django.template.exceptions.TemplateDoesNotExist: recommended_courses.html
INFO - 12-Jan-24 12:29:37 - C:\Users\Simon\proacted\AIacademia\academia_app\views.py changed, reloading.
ERROR - 12-Jan-24 12:34:19 - Internal Server Error: /recommend_courses
Traceback (most recent call last):
  File "C:\Users\Simon\AppData\Roaming\Python\Python311\site-packages\django\template\base.py", line 505, in parse
    compile_func = self.tags[command]
                   ~~~~~~~~~^^^^^^^^^
KeyError: 'static'

During handling of the above exception, another exception occurred:

Traceback (most recent call last):
  File "C:\Users\Simon\AppData\Roaming\Python\Python311\site-packages\django\core\handlers\exception.py", line 55, in inner
    response = get_response(request)
               ^^^^^^^^^^^^^^^^^^^^^
  File "C:\Users\Simon\AppData\Roaming\Python\Python311\site-packages\django\core\handlers\base.py", line 197, in _get_response
    response = wrapped_callback(request, *callback_args, **callback_kwargs)
               ^^^^^^^^^^^^^^^^^^^^^^^^^^^^^^^^^^^^^^^^^^^^^^^^^^^^^^^^^^^^
  File "C:\Users\Simon\proacted\AIacademia\academia_app\views.py", line 234, in recommend_courses
    return render(request, 'academia_app/recommended_courses.html', context)
           ^^^^^^^^^^^^^^^^^^^^^^^^^^^^^^^^^^^^^^^^^^^^^^^^^^^^^^^^^^^^^^^^^
  File "C:\Users\Simon\AppData\Roaming\Python\Python311\site-packages\django\shortcuts.py", line 24, in render
    content = loader.render_to_string(template_name, context, request, using=using)
              ^^^^^^^^^^^^^^^^^^^^^^^^^^^^^^^^^^^^^^^^^^^^^^^^^^^^^^^^^^^^^^^^^^^^^
  File "C:\Users\Simon\AppData\Roaming\Python\Python311\site-packages\django\template\loader.py", line 61, in render_to_string
    template = get_template(template_name, using=using)
               ^^^^^^^^^^^^^^^^^^^^^^^^^^^^^^^^^^^^^^^^
  File "C:\Users\Simon\AppData\Roaming\Python\Python311\site-packages\django\template\loader.py", line 15, in get_template
    return engine.get_template(template_name)
           ^^^^^^^^^^^^^^^^^^^^^^^^^^^^^^^^^^
  File "C:\Users\Simon\AppData\Roaming\Python\Python311\site-packages\django\template\backends\django.py", line 33, in get_template
    return Template(self.engine.get_template(template_name), self)
                    ^^^^^^^^^^^^^^^^^^^^^^^^^^^^^^^^^^^^^^^
  File "C:\Users\Simon\AppData\Roaming\Python\Python311\site-packages\django\template\engine.py", line 175, in get_template
    template, origin = self.find_template(template_name)
                       ^^^^^^^^^^^^^^^^^^^^^^^^^^^^^^^^^
  File "C:\Users\Simon\AppData\Roaming\Python\Python311\site-packages\django\template\engine.py", line 157, in find_template
    template = loader.get_template(name, skip=skip)
               ^^^^^^^^^^^^^^^^^^^^^^^^^^^^^^^^^^^^
  File "C:\Users\Simon\AppData\Roaming\Python\Python311\site-packages\django\template\loaders\cached.py", line 57, in get_template
    template = super().get_template(template_name, skip)
               ^^^^^^^^^^^^^^^^^^^^^^^^^^^^^^^^^^^^^^^^^
  File "C:\Users\Simon\AppData\Roaming\Python\Python311\site-packages\django\template\loaders\base.py", line 28, in get_template
    return Template(
           ^^^^^^^^^
  File "C:\Users\Simon\AppData\Roaming\Python\Python311\site-packages\django\template\base.py", line 154, in __init__
    self.nodelist = self.compile_nodelist()
                    ^^^^^^^^^^^^^^^^^^^^^^^
  File "C:\Users\Simon\AppData\Roaming\Python\Python311\site-packages\django\template\base.py", line 200, in compile_nodelist
    return parser.parse()
           ^^^^^^^^^^^^^^
  File "C:\Users\Simon\AppData\Roaming\Python\Python311\site-packages\django\template\base.py", line 507, in parse
    self.invalid_block_tag(token, command, parse_until)
  File "C:\Users\Simon\AppData\Roaming\Python\Python311\site-packages\django\template\base.py", line 568, in invalid_block_tag
    raise self.error(
django.template.exceptions.TemplateSyntaxError: Invalid block tag on line 7: 'static'. Did you forget to register or load this tag?
INFO - 12-Jan-24 12:39:51 - C:\Users\Simon\proacted\AIacademia\academia_app\views.py changed, reloading.
ERROR - 12-Jan-24 12:41:32 - Internal Server Error: /recommend_courses
Traceback (most recent call last):
  File "C:\Users\Simon\AppData\Roaming\Python\Python311\site-packages\django\core\handlers\exception.py", line 55, in inner
    response = get_response(request)
               ^^^^^^^^^^^^^^^^^^^^^
  File "C:\Users\Simon\AppData\Roaming\Python\Python311\site-packages\django\core\handlers\base.py", line 197, in _get_response
    response = wrapped_callback(request, *callback_args, **callback_kwargs)
               ^^^^^^^^^^^^^^^^^^^^^^^^^^^^^^^^^^^^^^^^^^^^^^^^^^^^^^^^^^^^
  File "C:\Users\Simon\proacted\AIacademia\academia_app\views.py", line 235, in recommend_courses
    return render(request, 'academia_app/recommended_courses.html', context)
           ^^^^^^^^^^^^^^^^^^^^^^^^^^^^^^^^^^^^^^^^^^^^^^^^^^^^^^^^^^^^^^^^^
  File "C:\Users\Simon\AppData\Roaming\Python\Python311\site-packages\django\shortcuts.py", line 24, in render
    content = loader.render_to_string(template_name, context, request, using=using)
              ^^^^^^^^^^^^^^^^^^^^^^^^^^^^^^^^^^^^^^^^^^^^^^^^^^^^^^^^^^^^^^^^^^^^^
  File "C:\Users\Simon\AppData\Roaming\Python\Python311\site-packages\django\template\loader.py", line 62, in render_to_string
    return template.render(context, request)
           ^^^^^^^^^^^^^^^^^^^^^^^^^^^^^^^^^
  File "C:\Users\Simon\AppData\Roaming\Python\Python311\site-packages\django\template\backends\django.py", line 61, in render
    return self.template.render(context)
           ^^^^^^^^^^^^^^^^^^^^^^^^^^^^^
  File "C:\Users\Simon\AppData\Roaming\Python\Python311\site-packages\django\template\base.py", line 175, in render
    return self._render(context)
           ^^^^^^^^^^^^^^^^^^^^^
  File "C:\Users\Simon\AppData\Roaming\Python\Python311\site-packages\django\template\base.py", line 167, in _render
    return self.nodelist.render(context)
           ^^^^^^^^^^^^^^^^^^^^^^^^^^^^^
  File "C:\Users\Simon\AppData\Roaming\Python\Python311\site-packages\django\template\base.py", line 1005, in render
    return SafeString("".join([node.render_annotated(context) for node in self]))
                              ^^^^^^^^^^^^^^^^^^^^^^^^^^^^^^^^^^^^^^^^^^^^^^^^^
  File "C:\Users\Simon\AppData\Roaming\Python\Python311\site-packages\django\template\base.py", line 1005, in <listcomp>
    return SafeString("".join([node.render_annotated(context) for node in self]))
                               ^^^^^^^^^^^^^^^^^^^^^^^^^^^^^^
  File "C:\Users\Simon\AppData\Roaming\Python\Python311\site-packages\django\template\base.py", line 966, in render_annotated
    return self.render(context)
           ^^^^^^^^^^^^^^^^^^^^
  File "C:\Users\Simon\AppData\Roaming\Python\Python311\site-packages\django\template\defaulttags.py", line 238, in render
    nodelist.append(node.render_annotated(context))
                    ^^^^^^^^^^^^^^^^^^^^^^^^^^^^^^
  File "C:\Users\Simon\AppData\Roaming\Python\Python311\site-packages\django\template\base.py", line 966, in render_annotated
    return self.render(context)
           ^^^^^^^^^^^^^^^^^^^^
  File "C:\Users\Simon\AppData\Roaming\Python\Python311\site-packages\django\template\defaulttags.py", line 471, in render
    url = reverse(view_name, args=args, kwargs=kwargs, current_app=current_app)
          ^^^^^^^^^^^^^^^^^^^^^^^^^^^^^^^^^^^^^^^^^^^^^^^^^^^^^^^^^^^^^^^^^^^^^
  File "C:\Users\Simon\AppData\Roaming\Python\Python311\site-packages\django\urls\base.py", line 88, in reverse
    return resolver._reverse_with_prefix(view, prefix, *args, **kwargs)
           ^^^^^^^^^^^^^^^^^^^^^^^^^^^^^^^^^^^^^^^^^^^^^^^^^^^^^^^^^^^^
  File "C:\Users\Simon\AppData\Roaming\Python\Python311\site-packages\django\urls\resolvers.py", line 828, in _reverse_with_prefix
    raise NoReverseMatch(msg)
django.urls.exceptions.NoReverseMatch: Reverse for 'course_detail' not found. 'course_detail' is not a valid view function or pattern name.
ERROR - 12-Jan-24 13:31:52 - Internal Server Error: /recommend_courses
Traceback (most recent call last):
  File "C:\Users\Simon\AppData\Roaming\Python\Python311\site-packages\django\core\handlers\exception.py", line 55, in inner
    response = get_response(request)
               ^^^^^^^^^^^^^^^^^^^^^
  File "C:\Users\Simon\AppData\Roaming\Python\Python311\site-packages\django\core\handlers\base.py", line 197, in _get_response
    response = wrapped_callback(request, *callback_args, **callback_kwargs)
               ^^^^^^^^^^^^^^^^^^^^^^^^^^^^^^^^^^^^^^^^^^^^^^^^^^^^^^^^^^^^
  File "C:\Users\Simon\proacted\AIacademia\academia_app\views.py", line 230, in recommend_courses
    recommendations = load_model(user_subjects_done, user_interests)
                      ^^^^^^^^^^^^^^^^^^^^^^^^^^^^^^^^^^^^^^^^^^^^^^
  File "C:\Users\Simon\proacted\AIacademia\python_scripts\recommender_clustering_pooling.py", line 76, in load_model
    objectives_tfidf_matrix = objectives_vectorizer.fit_transform(df['Course Objectives'])
                                                                  ~~^^^^^^^^^^^^^^^^^^^^^
  File "C:\Users\Simon\AppData\Roaming\Python\Python311\site-packages\pandas\core\frame.py", line 3896, in __getitem__
    indexer = self.columns.get_loc(key)
              ^^^^^^^^^^^^^^^^^^^^^^^^^
  File "C:\Users\Simon\AppData\Roaming\Python\Python311\site-packages\pandas\core\indexes\range.py", line 418, in get_loc
    raise KeyError(key)
KeyError: 'Course Objectives'
ERROR - 12-Jan-24 13:33:08 - Internal Server Error: /recommend_courses
Traceback (most recent call last):
  File "C:\Users\Simon\AppData\Roaming\Python\Python311\site-packages\django\core\handlers\exception.py", line 55, in inner
    response = get_response(request)
               ^^^^^^^^^^^^^^^^^^^^^
  File "C:\Users\Simon\AppData\Roaming\Python\Python311\site-packages\django\core\handlers\base.py", line 197, in _get_response
    response = wrapped_callback(request, *callback_args, **callback_kwargs)
               ^^^^^^^^^^^^^^^^^^^^^^^^^^^^^^^^^^^^^^^^^^^^^^^^^^^^^^^^^^^^
  File "C:\Users\Simon\proacted\AIacademia\academia_app\views.py", line 230, in recommend_courses
    recommendations = load_model(user_subjects_done, user_interests)
                      ^^^^^^^^^^^^^^^^^^^^^^^^^^^^^^^^^^^^^^^^^^^^^^
  File "C:\Users\Simon\proacted\AIacademia\python_scripts\recommender_clustering_pooling.py", line 76, in load_model
    objectives_tfidf_matrix = objectives_vectorizer.fit_transform(df['Course Objectives'])
                                                                  ~~^^^^^^^^^^^^^^^^^^^^^
  File "C:\Users\Simon\AppData\Roaming\Python\Python311\site-packages\pandas\core\frame.py", line 3896, in __getitem__
    indexer = self.columns.get_loc(key)
              ^^^^^^^^^^^^^^^^^^^^^^^^^
  File "C:\Users\Simon\AppData\Roaming\Python\Python311\site-packages\pandas\core\indexes\range.py", line 418, in get_loc
    raise KeyError(key)
KeyError: 'Course Objectives'
INFO - 12-Jan-24 13:40:32 - C:\Users\Simon\proacted\AIacademia\python_scripts\recommender_clustering_pooling.py changed, reloading.
INFO - 12-Jan-24 13:49:15 - C:\Users\Simon\proacted\AIacademia\academia_app\views.py changed, reloading.
ERROR - 12-Jan-24 13:49:34 - Internal Server Error: /recommend_courses
Traceback (most recent call last):
  File "C:\Users\Simon\AppData\Roaming\Python\Python311\site-packages\django\core\handlers\exception.py", line 55, in inner
    response = get_response(request)
               ^^^^^^^^^^^^^^^^^^^^^
  File "C:\Users\Simon\AppData\Roaming\Python\Python311\site-packages\django\core\handlers\base.py", line 197, in _get_response
    response = wrapped_callback(request, *callback_args, **callback_kwargs)
               ^^^^^^^^^^^^^^^^^^^^^^^^^^^^^^^^^^^^^^^^^^^^^^^^^^^^^^^^^^^^
  File "C:\Users\Simon\proacted\AIacademia\academia_app\views.py", line 232, in recommend_courses
    recommendations = load_model(user_subjects_done, user_interests)
                      ^^^^^^^^^^^^^^^^^^^^^^^^^^^^^^^^^^^^^^^^^^^^^^
  File "C:\Users\Simon\proacted\AIacademia\python_scripts\recommender_clustering_pooling.py", line 81, in load_model
    objectives_feature_names = objectives_vectorizer.get_feature_names_out()
                               ^^^^^^^^^^^^^^^^^^^^^^^^^^^^^^^^^^^^^^^^^^^^^
  File "C:\Users\Simon\AppData\Roaming\Python\Python311\site-packages\sklearn\feature_extraction\text.py", line 1485, in get_feature_names_out
    self._check_vocabulary()
  File "C:\Users\Simon\AppData\Roaming\Python\Python311\site-packages\sklearn\feature_extraction\text.py", line 508, in _check_vocabulary
    raise NotFittedError("Vocabulary not fitted or provided")
sklearn.exceptions.NotFittedError: Vocabulary not fitted or provided
ERROR - 12-Jan-24 13:53:09 - Internal Server Error: /recommend_courses
Traceback (most recent call last):
  File "C:\Users\Simon\AppData\Roaming\Python\Python311\site-packages\django\core\handlers\exception.py", line 55, in inner
    response = get_response(request)
               ^^^^^^^^^^^^^^^^^^^^^
  File "C:\Users\Simon\AppData\Roaming\Python\Python311\site-packages\django\core\handlers\base.py", line 197, in _get_response
    response = wrapped_callback(request, *callback_args, **callback_kwargs)
               ^^^^^^^^^^^^^^^^^^^^^^^^^^^^^^^^^^^^^^^^^^^^^^^^^^^^^^^^^^^^
  File "C:\Users\Simon\proacted\AIacademia\academia_app\views.py", line 232, in recommend_courses
    recommendations = load_model(user_subjects_done, user_interests)
                      ^^^^^^^^^^^^^^^^^^^^^^^^^^^^^^^^^^^^^^^^^^^^^^
  File "C:\Users\Simon\proacted\AIacademia\python_scripts\recommender_clustering_pooling.py", line 81, in load_model
    objectives_feature_names = objectives_vectorizer.get_feature_names_out()
                               ^^^^^^^^^^^^^^^^^^^^^^^^^^^^^^^^^^^^^^^^^^^^^
  File "C:\Users\Simon\AppData\Roaming\Python\Python311\site-packages\sklearn\feature_extraction\text.py", line 1485, in get_feature_names_out
    self._check_vocabulary()
  File "C:\Users\Simon\AppData\Roaming\Python\Python311\site-packages\sklearn\feature_extraction\text.py", line 508, in _check_vocabulary
    raise NotFittedError("Vocabulary not fitted or provided")
sklearn.exceptions.NotFittedError: Vocabulary not fitted or provided
WARNING - 17-Jan-24 14:56:41 - Not Found: /favicon.ico
ERROR - 17-Jan-24 14:57:32 - Internal Server Error: /recommend_courses
Traceback (most recent call last):
  File "C:\Users\Simon\AppData\Roaming\Python\Python311\site-packages\django\core\handlers\exception.py", line 55, in inner
    response = get_response(request)
               ^^^^^^^^^^^^^^^^^^^^^
  File "C:\Users\Simon\AppData\Roaming\Python\Python311\site-packages\django\core\handlers\base.py", line 197, in _get_response
    response = wrapped_callback(request, *callback_args, **callback_kwargs)
               ^^^^^^^^^^^^^^^^^^^^^^^^^^^^^^^^^^^^^^^^^^^^^^^^^^^^^^^^^^^^
  File "C:\Users\Simon\proacted\AIacademia\academia_app\views.py", line 230, in recommend_courses
    recommendations = load_model(user_subjects_done, user_interests)
                      ^^^^^^^^^^^^^^^^^^^^^^^^^^^^^^^^^^^^^^^^^^^^^^
  File "C:\Users\Simon\proacted\AIacademia\python_scripts\recommender_clustering_pooling.py", line 81, in load_model
    objectives_feature_names = objectives_vectorizer.get_feature_names_out()
                               ^^^^^^^^^^^^^^^^^^^^^^^^^^^^^^^^^^^^^^^^^^^^^
  File "C:\Users\Simon\AppData\Roaming\Python\Python311\site-packages\sklearn\feature_extraction\text.py", line 1485, in get_feature_names_out
    self._check_vocabulary()
  File "C:\Users\Simon\AppData\Roaming\Python\Python311\site-packages\sklearn\feature_extraction\text.py", line 508, in _check_vocabulary
    raise NotFittedError("Vocabulary not fitted or provided")
sklearn.exceptions.NotFittedError: Vocabulary not fitted or provided
INFO - 17-Jan-24 15:01:24 - C:\Users\Simon\proacted\AIacademia\python_scripts\recommender_clustering_pooling.py changed, reloading.
INFO - 17-Jan-24 15:01:55 - C:\Users\Simon\proacted\AIacademia\python_scripts\recommender_clustering_pooling.py changed, reloading.
INFO - 17-Jan-24 15:09:05 - C:\Users\Simon\proacted\AIacademia\python_scripts\recommender_clustering_pooling.py changed, reloading.
ERROR - 17-Jan-24 15:10:00 - Internal Server Error: /recommend_courses
Traceback (most recent call last):
  File "C:\Users\Simon\AppData\Roaming\Python\Python311\site-packages\django\core\handlers\exception.py", line 55, in inner
    response = get_response(request)
               ^^^^^^^^^^^^^^^^^^^^^
  File "C:\Users\Simon\AppData\Roaming\Python\Python311\site-packages\django\core\handlers\base.py", line 197, in _get_response
    response = wrapped_callback(request, *callback_args, **callback_kwargs)
               ^^^^^^^^^^^^^^^^^^^^^^^^^^^^^^^^^^^^^^^^^^^^^^^^^^^^^^^^^^^^
  File "C:\Users\Simon\proacted\AIacademia\academia_app\views.py", line 230, in recommend_courses
    recommendations = load_model(user_subjects_done, user_interests)
                      ^^^^^^^^^^^^^^^^^^^^^^^^^^^^^^^^^^^^^^^^^^^^^^
  File "C:\Users\Simon\proacted\AIacademia\python_scripts\recommender_clustering_pooling.py", line 120, in load_model
    df['Vectorized Objectives'] = df['Tokenized Objectives'].apply(lambda x: vectorize_sentences(x, model, objectives_vectorizer))
                                  ^^^^^^^^^^^^^^^^^^^^^^^^^^^^^^^^^^^^^^^^^^^^^^^^^^^^^^^^^^^^^^^^^^^^^^^^^^^^^^^^^^^^^^^^^^^^^^^^
  File "C:\Users\Simon\AppData\Roaming\Python\Python311\site-packages\pandas\core\series.py", line 4760, in apply
    ).apply()
      ^^^^^^^
  File "C:\Users\Simon\AppData\Roaming\Python\Python311\site-packages\pandas\core\apply.py", line 1207, in apply
    return self.apply_standard()
           ^^^^^^^^^^^^^^^^^^^^^
  File "C:\Users\Simon\AppData\Roaming\Python\Python311\site-packages\pandas\core\apply.py", line 1287, in apply_standard
    mapped = obj._map_values(
             ^^^^^^^^^^^^^^^^
  File "C:\Users\Simon\AppData\Roaming\Python\Python311\site-packages\pandas\core\base.py", line 921, in _map_values
    return algorithms.map_array(arr, mapper, na_action=na_action, convert=convert)
           ^^^^^^^^^^^^^^^^^^^^^^^^^^^^^^^^^^^^^^^^^^^^^^^^^^^^^^^^^^^^^^^^^^^^^^^
  File "C:\Users\Simon\AppData\Roaming\Python\Python311\site-packages\pandas\core\algorithms.py", line 1814, in map_array
    return lib.map_infer(values, mapper, convert=convert)
           ^^^^^^^^^^^^^^^^^^^^^^^^^^^^^^^^^^^^^^^^^^^^^^
  File "lib.pyx", line 2917, in pandas._libs.lib.map_infer
  File "C:\Users\Simon\proacted\AIacademia\python_scripts\recommender_clustering_pooling.py", line 120, in <lambda>
    df['Vectorized Objectives'] = df['Tokenized Objectives'].apply(lambda x: vectorize_sentences(x, model, objectives_vectorizer))
                                                                             ^^^^^^^^^^^^^^^^^^^^^^^^^^^^^^^^^^^^^^^^^^^^^^^^^^^^
  File "C:\Users\Simon\proacted\AIacademia\python_scripts\recommender_clustering_pooling.py", line 98, in vectorize_sentences
    feature_names = tfidf_vectorizer.get_feature_names_out()
                    ^^^^^^^^^^^^^^^^^^^^^^^^^^^^^^^^^^^^^^^^
  File "C:\Users\Simon\AppData\Roaming\Python\Python311\site-packages\sklearn\feature_extraction\text.py", line 1485, in get_feature_names_out
    self._check_vocabulary()
  File "C:\Users\Simon\AppData\Roaming\Python\Python311\site-packages\sklearn\feature_extraction\text.py", line 508, in _check_vocabulary
    raise NotFittedError("Vocabulary not fitted or provided")
sklearn.exceptions.NotFittedError: Vocabulary not fitted or provided
ERROR - 17-Jan-24 15:21:09 - Internal Server Error: /recommend_courses
Traceback (most recent call last):
  File "C:\Users\Simon\AppData\Roaming\Python\Python311\site-packages\django\core\handlers\exception.py", line 55, in inner
    response = get_response(request)
               ^^^^^^^^^^^^^^^^^^^^^
  File "C:\Users\Simon\AppData\Roaming\Python\Python311\site-packages\django\core\handlers\base.py", line 197, in _get_response
    response = wrapped_callback(request, *callback_args, **callback_kwargs)
               ^^^^^^^^^^^^^^^^^^^^^^^^^^^^^^^^^^^^^^^^^^^^^^^^^^^^^^^^^^^^
  File "C:\Users\Simon\proacted\AIacademia\academia_app\views.py", line 230, in recommend_courses
    recommendations = load_model(user_subjects_done, user_interests)
                      ^^^^^^^^^^^^^^^^^^^^^^^^^^^^^^^^^^^^^^^^^^^^^^
  File "C:\Users\Simon\proacted\AIacademia\python_scripts\recommender_clustering_pooling.py", line 246, in load_model
    vectorized_activities_enjoyed = clustered_weighted_vector(activities_enjoyed, model, generalinfoandabout_vectorizer)
                                   ^^^^^^^^^^^^^^^^^^^^^^^^^^^^^^^^^^^^^^^^^^^^^^^^^^^^^^^^^^^^^^^^^^^^^^^^^^^^^^^^^^^^
  File "C:\Users\Simon\proacted\AIacademia\python_scripts\recommender_clustering_pooling.py", line 221, in clustered_weighted_vector
    kmeans.fit(word_vectors)
  File "C:\Users\Simon\AppData\Roaming\Python\Python311\site-packages\sklearn\base.py", line 1152, in wrapper
    return fit_method(estimator, *args, **kwargs)
           ^^^^^^^^^^^^^^^^^^^^^^^^^^^^^^^^^^^^^^
  File "C:\Users\Simon\AppData\Roaming\Python\Python311\site-packages\sklearn\cluster\_kmeans.py", line 1484, in fit
    self._check_params_vs_input(X)
  File "C:\Users\Simon\AppData\Roaming\Python\Python311\site-packages\sklearn\cluster\_kmeans.py", line 1416, in _check_params_vs_input
    super()._check_params_vs_input(X, default_n_init=10)
  File "C:\Users\Simon\AppData\Roaming\Python\Python311\site-packages\sklearn\cluster\_kmeans.py", line 866, in _check_params_vs_input
    raise ValueError(
ValueError: n_samples=6 should be >= n_clusters=7.
