ERROR - 11-Jan-24 16:55:51 - Internal Server Error: /recommend_courses
Traceback (most recent call last):
  File "C:\Users\Simon\AppData\Roaming\Python\Python311\site-packages\django\core\handlers\exception.py", line 55, in inner
    response = get_response(request)
               ^^^^^^^^^^^^^^^^^^^^^
  File "C:\Users\Simon\AppData\Roaming\Python\Python311\site-packages\django\core\handlers\base.py", line 197, in _get_response
    response = wrapped_callback(request, *callback_args, **callback_kwargs)
               ^^^^^^^^^^^^^^^^^^^^^^^^^^^^^^^^^^^^^^^^^^^^^^^^^^^^^^^^^^^^
  File "C:\Users\Simon\proacted\AIacademia\academia_app\views.py", line 225, in recommend_courses
    recommendations = load_model(user_subjects_done, user_interests)
                      ^^^^^^^^^^^^^^^^^^^^^^^^^^^^^^^^^^^^^^^^^^^^^^
  File "C:\Users\Simon\proacted\AIacademia\python_scripts\recommender_clustering_pooling.py", line 85, in load_model
    objectives_tfidf_matrix = objectives_vectorizer.fit_transform(df['Course Objectives'])
                                                                  ~~^^^^^^^^^^^^^^^^^^^^^
  File "C:\Users\Simon\AppData\Roaming\Python\Python311\site-packages\pandas\core\frame.py", line 3896, in __getitem__
    indexer = self.columns.get_loc(key)
              ^^^^^^^^^^^^^^^^^^^^^^^^^
  File "C:\Users\Simon\AppData\Roaming\Python\Python311\site-packages\pandas\core\indexes\range.py", line 418, in get_loc
    raise KeyError(key)
KeyError: 'Course Objectives'
INFO - 11-Jan-24 16:57:20 - C:\Users\Simon\proacted\AIacademia\academia_app\urls.py changed, reloading.
INFO - 11-Jan-24 17:03:45 - C:\Users\Simon\proacted\AIacademia\academia_app\views.py changed, reloading.
INFO - 11-Jan-24 17:15:55 - C:\Users\Simon\proacted\AIacademia\academia_app\urls.py changed, reloading.
INFO - 11-Jan-24 17:16:16 - C:\Users\Simon\proacted\AIacademia\academia_app\views.py changed, reloading.
INFO - 11-Jan-24 17:16:42 - C:\Users\Simon\proacted\AIacademia\academia_app\views.py changed, reloading.
ERROR - 11-Jan-24 17:23:29 - Internal Server Error: /recommend_courses
Traceback (most recent call last):
  File "C:\Users\Simon\AppData\Roaming\Python\Python311\site-packages\django\core\handlers\exception.py", line 55, in inner
    response = get_response(request)
               ^^^^^^^^^^^^^^^^^^^^^
  File "C:\Users\Simon\AppData\Roaming\Python\Python311\site-packages\django\core\handlers\base.py", line 197, in _get_response
    response = wrapped_callback(request, *callback_args, **callback_kwargs)
               ^^^^^^^^^^^^^^^^^^^^^^^^^^^^^^^^^^^^^^^^^^^^^^^^^^^^^^^^^^^^
  File "C:\Users\Simon\proacted\AIacademia\academia_app\views.py", line 226, in recommend_courses
    recommendations = load_model(user_subjects_done, user_interests)
                      ^^^^^^^^^^^^^^^^^^^^^^^^^^^^^^^^^^^^^^^^^^^^^^
  File "C:\Users\Simon\proacted\AIacademia\python_scripts\recommender_clustering_pooling.py", line 85, in load_model
    objectives_tfidf_matrix = objectives_vectorizer.fit_transform(df['Course Objectives'])
                                                                  ~~^^^^^^^^^^^^^^^^^^^^^
  File "C:\Users\Simon\AppData\Roaming\Python\Python311\site-packages\pandas\core\frame.py", line 3896, in __getitem__
    indexer = self.columns.get_loc(key)
              ^^^^^^^^^^^^^^^^^^^^^^^^^
  File "C:\Users\Simon\AppData\Roaming\Python\Python311\site-packages\pandas\core\indexes\range.py", line 418, in get_loc
    raise KeyError(key)
KeyError: 'Course Objectives'
ERROR - 11-Jan-24 17:23:38 - Internal Server Error: /recommend_courses
Traceback (most recent call last):
  File "C:\Users\Simon\AppData\Roaming\Python\Python311\site-packages\django\core\handlers\exception.py", line 55, in inner
    response = get_response(request)
               ^^^^^^^^^^^^^^^^^^^^^
  File "C:\Users\Simon\AppData\Roaming\Python\Python311\site-packages\django\core\handlers\base.py", line 197, in _get_response
    response = wrapped_callback(request, *callback_args, **callback_kwargs)
               ^^^^^^^^^^^^^^^^^^^^^^^^^^^^^^^^^^^^^^^^^^^^^^^^^^^^^^^^^^^^
  File "C:\Users\Simon\proacted\AIacademia\academia_app\views.py", line 226, in recommend_courses
    recommendations = load_model(user_subjects_done, user_interests)
                      ^^^^^^^^^^^^^^^^^^^^^^^^^^^^^^^^^^^^^^^^^^^^^^
  File "C:\Users\Simon\proacted\AIacademia\python_scripts\recommender_clustering_pooling.py", line 85, in load_model
    objectives_tfidf_matrix = objectives_vectorizer.fit_transform(df['Course Objectives'])
                                                                  ~~^^^^^^^^^^^^^^^^^^^^^
  File "C:\Users\Simon\AppData\Roaming\Python\Python311\site-packages\pandas\core\frame.py", line 3896, in __getitem__
    indexer = self.columns.get_loc(key)
              ^^^^^^^^^^^^^^^^^^^^^^^^^
  File "C:\Users\Simon\AppData\Roaming\Python\Python311\site-packages\pandas\core\indexes\range.py", line 418, in get_loc
    raise KeyError(key)
KeyError: 'Course Objectives'
