INFO || 10-Jun-24 01:41:09 || Pro-Act-Ed 2024 Recommender Engine Initialized
INFO || 10-Jun-24 01:41:34 || time recommender model has used: 25.71858024597168
INFO || 10-Jun-24 01:41:37 || S-Bert 2024 Recommender Engine Initialized
INFO || 10-Jun-24 01:41:37 || Load pretrained SentenceTransformer: all-MiniLM-L6-v2
DEBUG || 10-Jun-24 01:41:37 || Starting new HTTPS connection (1): huggingface.co:443
DEBUG || 10-Jun-24 01:41:39 || https://huggingface.co:443 "HEAD /sentence-transformers/all-MiniLM-L6-v2/resolve/main/modules.json HTTP/1.1" 200 0
DEBUG || 10-Jun-24 01:41:39 || https://huggingface.co:443 "HEAD /sentence-transformers/all-MiniLM-L6-v2/resolve/main/config_sentence_transformers.json HTTP/1.1" 200 0
DEBUG || 10-Jun-24 01:41:39 || https://huggingface.co:443 "HEAD /sentence-transformers/all-MiniLM-L6-v2/resolve/main/README.md HTTP/1.1" 200 0
DEBUG || 10-Jun-24 01:41:40 || https://huggingface.co:443 "HEAD /sentence-transformers/all-MiniLM-L6-v2/resolve/main/modules.json HTTP/1.1" 200 0
DEBUG || 10-Jun-24 01:41:40 || https://huggingface.co:443 "HEAD /sentence-transformers/all-MiniLM-L6-v2/resolve/main/sentence_bert_config.json HTTP/1.1" 200 0
DEBUG || 10-Jun-24 01:41:41 || https://huggingface.co:443 "HEAD /sentence-transformers/all-MiniLM-L6-v2/resolve/main/config.json HTTP/1.1" 200 0
DEBUG || 10-Jun-24 01:41:42 || https://huggingface.co:443 "HEAD /sentence-transformers/all-MiniLM-L6-v2/resolve/main/tokenizer_config.json HTTP/1.1" 200 0
DEBUG || 10-Jun-24 01:41:42 || https://huggingface.co:443 "GET /api/models/sentence-transformers/all-MiniLM-L6-v2/revision/main HTTP/1.1" 200 6132
INFO || 10-Jun-24 01:41:42 || Use pytorch device_name: cpu
INFO || 10-Jun-24 01:44:41 || Pro-Act-Ed 2024 Recommender Engine Initialized
INFO || 10-Jun-24 01:45:04 || time recommender model has used: 24.09771156311035
INFO || 10-Jun-24 13:53:27 || Pro-Act-Ed 2024 Recommender Engine Initialized
INFO || 10-Jun-24 13:54:01 || time recommender model has used: 37.318135499954224
INFO || 10-Jun-24 13:54:10 || S-Bert 2024 Recommender Engine Initialized
INFO || 10-Jun-24 13:54:10 || Load pretrained SentenceTransformer: all-MiniLM-L6-v2
DEBUG || 10-Jun-24 13:54:10 || Starting new HTTPS connection (1): huggingface.co:443
DEBUG || 10-Jun-24 13:54:12 || https://huggingface.co:443 "HEAD /sentence-transformers/all-MiniLM-L6-v2/resolve/main/modules.json HTTP/1.1" 200 0
DEBUG || 10-Jun-24 13:54:12 || https://huggingface.co:443 "HEAD /sentence-transformers/all-MiniLM-L6-v2/resolve/main/config_sentence_transformers.json HTTP/1.1" 200 0
DEBUG || 10-Jun-24 13:54:12 || https://huggingface.co:443 "HEAD /sentence-transformers/all-MiniLM-L6-v2/resolve/main/README.md HTTP/1.1" 200 0
DEBUG || 10-Jun-24 13:54:13 || https://huggingface.co:443 "HEAD /sentence-transformers/all-MiniLM-L6-v2/resolve/main/modules.json HTTP/1.1" 200 0
DEBUG || 10-Jun-24 13:54:13 || https://huggingface.co:443 "HEAD /sentence-transformers/all-MiniLM-L6-v2/resolve/main/sentence_bert_config.json HTTP/1.1" 200 0
DEBUG || 10-Jun-24 13:54:14 || https://huggingface.co:443 "HEAD /sentence-transformers/all-MiniLM-L6-v2/resolve/main/config.json HTTP/1.1" 200 0
DEBUG || 10-Jun-24 13:54:15 || https://huggingface.co:443 "HEAD /sentence-transformers/all-MiniLM-L6-v2/resolve/main/tokenizer_config.json HTTP/1.1" 200 0
DEBUG || 10-Jun-24 13:54:16 || https://huggingface.co:443 "GET /api/models/sentence-transformers/all-MiniLM-L6-v2/revision/main HTTP/1.1" 200 6132
INFO || 10-Jun-24 13:54:16 || Use pytorch device_name: cpu
INFO || 10-Jun-24 13:55:25 || Pro-Act-Ed 2024 Recommender Engine Initialized
INFO || 10-Jun-24 13:55:53 || time recommender model has used: 30.231669425964355
INFO || 10-Jun-24 13:56:01 || S-Bert 2024 Recommender Engine Initialized
INFO || 10-Jun-24 13:56:01 || Load pretrained SentenceTransformer: all-MiniLM-L6-v2
DEBUG || 10-Jun-24 13:56:01 || Starting new HTTPS connection (1): huggingface.co:443
DEBUG || 10-Jun-24 13:56:02 || https://huggingface.co:443 "HEAD /sentence-transformers/all-MiniLM-L6-v2/resolve/main/modules.json HTTP/1.1" 200 0
DEBUG || 10-Jun-24 13:56:02 || https://huggingface.co:443 "HEAD /sentence-transformers/all-MiniLM-L6-v2/resolve/main/config_sentence_transformers.json HTTP/1.1" 200 0
DEBUG || 10-Jun-24 13:56:02 || https://huggingface.co:443 "HEAD /sentence-transformers/all-MiniLM-L6-v2/resolve/main/README.md HTTP/1.1" 200 0
DEBUG || 10-Jun-24 13:56:03 || https://huggingface.co:443 "HEAD /sentence-transformers/all-MiniLM-L6-v2/resolve/main/modules.json HTTP/1.1" 200 0
DEBUG || 10-Jun-24 13:56:03 || https://huggingface.co:443 "HEAD /sentence-transformers/all-MiniLM-L6-v2/resolve/main/sentence_bert_config.json HTTP/1.1" 200 0
DEBUG || 10-Jun-24 13:56:04 || https://huggingface.co:443 "HEAD /sentence-transformers/all-MiniLM-L6-v2/resolve/main/config.json HTTP/1.1" 200 0
DEBUG || 10-Jun-24 13:56:06 || https://huggingface.co:443 "HEAD /sentence-transformers/all-MiniLM-L6-v2/resolve/main/tokenizer_config.json HTTP/1.1" 200 0
DEBUG || 10-Jun-24 13:56:06 || https://huggingface.co:443 "GET /api/models/sentence-transformers/all-MiniLM-L6-v2/revision/main HTTP/1.1" 200 6132
INFO || 10-Jun-24 13:56:06 || Use pytorch device_name: cpu
ERROR || 10-Jun-24 17:51:34 || Internal Server Error: /check_new_messages/
Traceback (most recent call last):
  File "C:\Users\Simon\AppData\Roaming\Python\Python311\site-packages\django\db\models\fields\__init__.py", line 2053, in get_prep_value
    return int(value)
           ^^^^^^^^^^
TypeError: int() argument must be a string, a bytes-like object or a real number, not 'SimpleLazyObject'

The above exception was the direct cause of the following exception:

Traceback (most recent call last):
  File "C:\Users\Simon\AppData\Roaming\Python\Python311\site-packages\django\core\handlers\exception.py", line 55, in inner
    response = get_response(request)
               ^^^^^^^^^^^^^^^^^^^^^
  File "C:\Users\Simon\AppData\Roaming\Python\Python311\site-packages\django\core\handlers\base.py", line 197, in _get_response
    response = wrapped_callback(request, *callback_args, **callback_kwargs)
               ^^^^^^^^^^^^^^^^^^^^^^^^^^^^^^^^^^^^^^^^^^^^^^^^^^^^^^^^^^^^
  File "C:\Users\Simon\proacted\AIacademia\academia_app\views.py", line 263, in check_new_messages
    has_new_messages = NewMessageNotification.objects.filter(user=request.user, is_new=True).exists()
                       ^^^^^^^^^^^^^^^^^^^^^^^^^^^^^^^^^^^^^^^^^^^^^^^^^^^^^^^^^^^^^^^^^^^^^
  File "C:\Users\Simon\AppData\Roaming\Python\Python311\site-packages\django\db\models\manager.py", line 87, in manager_method
    return getattr(self.get_queryset(), name)(*args, **kwargs)
           ^^^^^^^^^^^^^^^^^^^^^^^^^^^^^^^^^^^^^^^^^^^^^^^^^^^
  File "C:\Users\Simon\AppData\Roaming\Python\Python311\site-packages\django\db\models\query.py", line 1436, in filter
    return self._filter_or_exclude(False, args, kwargs)
           ^^^^^^^^^^^^^^^^^^^^^^^^^^^^^^^^^^^^^^^^^^^^
  File "C:\Users\Simon\AppData\Roaming\Python\Python311\site-packages\django\db\models\query.py", line 1454, in _filter_or_exclude
    clone._filter_or_exclude_inplace(negate, args, kwargs)
  File "C:\Users\Simon\AppData\Roaming\Python\Python311\site-packages\django\db\models\query.py", line 1461, in _filter_or_exclude_inplace
    self._query.add_q(Q(*args, **kwargs))
  File "C:\Users\Simon\AppData\Roaming\Python\Python311\site-packages\django\db\models\sql\query.py", line 1545, in add_q
    clause, _ = self._add_q(q_object, self.used_aliases)
                ^^^^^^^^^^^^^^^^^^^^^^^^^^^^^^^^^^^^^^^^
  File "C:\Users\Simon\AppData\Roaming\Python\Python311\site-packages\django\db\models\sql\query.py", line 1576, in _add_q
    child_clause, needed_inner = self.build_filter(
                                 ^^^^^^^^^^^^^^^^^^
  File "C:\Users\Simon\AppData\Roaming\Python\Python311\site-packages\django\db\models\sql\query.py", line 1491, in build_filter
    condition = self.build_lookup(lookups, col, value)
                ^^^^^^^^^^^^^^^^^^^^^^^^^^^^^^^^^^^^^^
  File "C:\Users\Simon\AppData\Roaming\Python\Python311\site-packages\django\db\models\sql\query.py", line 1318, in build_lookup
    lookup = lookup_class(lhs, rhs)
             ^^^^^^^^^^^^^^^^^^^^^^
  File "C:\Users\Simon\AppData\Roaming\Python\Python311\site-packages\django\db\models\lookups.py", line 27, in __init__
    self.rhs = self.get_prep_lookup()
               ^^^^^^^^^^^^^^^^^^^^^^
  File "C:\Users\Simon\AppData\Roaming\Python\Python311\site-packages\django\db\models\fields\related_lookups.py", line 166, in get_prep_lookup
    self.rhs = target_field.get_prep_value(self.rhs)
               ^^^^^^^^^^^^^^^^^^^^^^^^^^^^^^^^^^^^^
  File "C:\Users\Simon\AppData\Roaming\Python\Python311\site-packages\django\db\models\fields\__init__.py", line 2055, in get_prep_value
    raise e.__class__(
TypeError: Field 'id' expected a number but got <SimpleLazyObject: <django.contrib.auth.models.AnonymousUser object at 0x0000023C5728AED0>>.
WARNING || 10-Jun-24 17:51:34 || Not Found: /ws/academia_app/
WARNING || 10-Jun-24 17:51:42 || From C:\Users\Simon\AppData\Roaming\Python\Python311\site-packages\keras\src\backend.py:1398: The name tf.executing_eagerly_outside_functions is deprecated. Please use tf.compat.v1.executing_eagerly_outside_functions instead.

WARNING || 10-Jun-24 17:51:43 || From C:\Users\Simon\AppData\Roaming\Python\Python311\site-packages\keras\src\optimizers\__init__.py:309: The name tf.train.Optimizer is deprecated. Please use tf.compat.v1.train.Optimizer instead.

INFO || 10-Jun-24 19:30:58 || C:\Users\Simon\proacted\AIacademia\academia_app\urls.py changed, reloading.
WARNING || 11-Jun-24 22:06:27 || Not Found: /favicon.ico
ERROR || 11-Jun-24 22:06:29 || Internal Server Error: /check_new_messages/
Traceback (most recent call last):
  File "C:\Users\Simon\AppData\Roaming\Python\Python311\site-packages\django\db\models\fields\__init__.py", line 2053, in get_prep_value
    return int(value)
           ^^^^^^^^^^
TypeError: int() argument must be a string, a bytes-like object or a real number, not 'SimpleLazyObject'

The above exception was the direct cause of the following exception:

Traceback (most recent call last):
  File "C:\Users\Simon\AppData\Roaming\Python\Python311\site-packages\django\core\handlers\exception.py", line 55, in inner
    response = get_response(request)
               ^^^^^^^^^^^^^^^^^^^^^
  File "C:\Users\Simon\AppData\Roaming\Python\Python311\site-packages\django\core\handlers\base.py", line 197, in _get_response
    response = wrapped_callback(request, *callback_args, **callback_kwargs)
               ^^^^^^^^^^^^^^^^^^^^^^^^^^^^^^^^^^^^^^^^^^^^^^^^^^^^^^^^^^^^
  File "C:\Users\Simon\proacted\AIacademia\academia_app\views.py", line 298, in check_new_messages
    has_new_messages = NewMessageNotification.objects.filter(user=request.user, is_new=True).exists()
                       ^^^^^^^^^^^^^^^^^^^^^^^^^^^^^^^^^^^^^^^^^^^^^^^^^^^^^^^^^^^^^^^^^^^^^
  File "C:\Users\Simon\AppData\Roaming\Python\Python311\site-packages\django\db\models\manager.py", line 87, in manager_method
    return getattr(self.get_queryset(), name)(*args, **kwargs)
           ^^^^^^^^^^^^^^^^^^^^^^^^^^^^^^^^^^^^^^^^^^^^^^^^^^^
  File "C:\Users\Simon\AppData\Roaming\Python\Python311\site-packages\django\db\models\query.py", line 1436, in filter
    return self._filter_or_exclude(False, args, kwargs)
           ^^^^^^^^^^^^^^^^^^^^^^^^^^^^^^^^^^^^^^^^^^^^
  File "C:\Users\Simon\AppData\Roaming\Python\Python311\site-packages\django\db\models\query.py", line 1454, in _filter_or_exclude
    clone._filter_or_exclude_inplace(negate, args, kwargs)
  File "C:\Users\Simon\AppData\Roaming\Python\Python311\site-packages\django\db\models\query.py", line 1461, in _filter_or_exclude_inplace
    self._query.add_q(Q(*args, **kwargs))
  File "C:\Users\Simon\AppData\Roaming\Python\Python311\site-packages\django\db\models\sql\query.py", line 1545, in add_q
    clause, _ = self._add_q(q_object, self.used_aliases)
                ^^^^^^^^^^^^^^^^^^^^^^^^^^^^^^^^^^^^^^^^
  File "C:\Users\Simon\AppData\Roaming\Python\Python311\site-packages\django\db\models\sql\query.py", line 1576, in _add_q
    child_clause, needed_inner = self.build_filter(
                                 ^^^^^^^^^^^^^^^^^^
  File "C:\Users\Simon\AppData\Roaming\Python\Python311\site-packages\django\db\models\sql\query.py", line 1491, in build_filter
    condition = self.build_lookup(lookups, col, value)
                ^^^^^^^^^^^^^^^^^^^^^^^^^^^^^^^^^^^^^^
  File "C:\Users\Simon\AppData\Roaming\Python\Python311\site-packages\django\db\models\sql\query.py", line 1318, in build_lookup
    lookup = lookup_class(lhs, rhs)
             ^^^^^^^^^^^^^^^^^^^^^^
  File "C:\Users\Simon\AppData\Roaming\Python\Python311\site-packages\django\db\models\lookups.py", line 27, in __init__
    self.rhs = self.get_prep_lookup()
               ^^^^^^^^^^^^^^^^^^^^^^
  File "C:\Users\Simon\AppData\Roaming\Python\Python311\site-packages\django\db\models\fields\related_lookups.py", line 166, in get_prep_lookup
    self.rhs = target_field.get_prep_value(self.rhs)
               ^^^^^^^^^^^^^^^^^^^^^^^^^^^^^^^^^^^^^
  File "C:\Users\Simon\AppData\Roaming\Python\Python311\site-packages\django\db\models\fields\__init__.py", line 2055, in get_prep_value
    raise e.__class__(
TypeError: Field 'id' expected a number but got <SimpleLazyObject: <django.contrib.auth.models.AnonymousUser object at 0x000001C214B82E90>>.
WARNING || 11-Jun-24 22:06:29 || Not Found: /ws/academia_app/
ERROR || 11-Jun-24 22:06:45 || Internal Server Error: /auth/login/
Traceback (most recent call last):
  File "C:\Users\Simon\AppData\Roaming\Python\Python311\site-packages\django\db\backends\utils.py", line 89, in _execute
    return self.cursor.execute(sql, params)
           ^^^^^^^^^^^^^^^^^^^^^^^^^^^^^^^^
  File "C:\Users\Simon\AppData\Roaming\Python\Python311\site-packages\django\db\backends\sqlite3\base.py", line 328, in execute
    return super().execute(query, params)
           ^^^^^^^^^^^^^^^^^^^^^^^^^^^^^^
sqlite3.OperationalError: no such column: academia_app_baseuser.role

The above exception was the direct cause of the following exception:

Traceback (most recent call last):
  File "C:\Users\Simon\AppData\Roaming\Python\Python311\site-packages\django\core\handlers\exception.py", line 55, in inner
    response = get_response(request)
               ^^^^^^^^^^^^^^^^^^^^^
  File "C:\Users\Simon\AppData\Roaming\Python\Python311\site-packages\django\core\handlers\base.py", line 197, in _get_response
    response = wrapped_callback(request, *callback_args, **callback_kwargs)
               ^^^^^^^^^^^^^^^^^^^^^^^^^^^^^^^^^^^^^^^^^^^^^^^^^^^^^^^^^^^^
  File "C:\Users\Simon\proacted\AIacademia\academia_app\views.py", line 44, in login_view
    user = authenticate(request, username=username, password=password)
           ^^^^^^^^^^^^^^^^^^^^^^^^^^^^^^^^^^^^^^^^^^^^^^^^^^^^^^^^^^^
  File "C:\Users\Simon\AppData\Roaming\Python\Python311\site-packages\django\views\decorators\debug.py", line 42, in sensitive_variables_wrapper
    return func(*func_args, **func_kwargs)
           ^^^^^^^^^^^^^^^^^^^^^^^^^^^^^^^
  File "C:\Users\Simon\AppData\Roaming\Python\Python311\site-packages\django\contrib\auth\__init__.py", line 77, in authenticate
    user = backend.authenticate(request, **credentials)
           ^^^^^^^^^^^^^^^^^^^^^^^^^^^^^^^^^^^^^^^^^^^^
  File "C:\Users\Simon\AppData\Roaming\Python\Python311\site-packages\django\contrib\auth\backends.py", line 46, in authenticate
    user = UserModel._default_manager.get_by_natural_key(username)
           ^^^^^^^^^^^^^^^^^^^^^^^^^^^^^^^^^^^^^^^^^^^^^^^^^^^^^^^
  File "C:\Users\Simon\AppData\Roaming\Python\Python311\site-packages\django\contrib\auth\base_user.py", line 54, in get_by_natural_key
    return self.get(**{self.model.USERNAME_FIELD: username})
           ^^^^^^^^^^^^^^^^^^^^^^^^^^^^^^^^^^^^^^^^^^^^^^^^^
  File "C:\Users\Simon\AppData\Roaming\Python\Python311\site-packages\django\db\models\manager.py", line 87, in manager_method
    return getattr(self.get_queryset(), name)(*args, **kwargs)
           ^^^^^^^^^^^^^^^^^^^^^^^^^^^^^^^^^^^^^^^^^^^^^^^^^^^
  File "C:\Users\Simon\AppData\Roaming\Python\Python311\site-packages\django\db\models\query.py", line 633, in get
    num = len(clone)
          ^^^^^^^^^^
  File "C:\Users\Simon\AppData\Roaming\Python\Python311\site-packages\django\db\models\query.py", line 380, in __len__
    self._fetch_all()
  File "C:\Users\Simon\AppData\Roaming\Python\Python311\site-packages\django\db\models\query.py", line 1881, in _fetch_all
    self._result_cache = list(self._iterable_class(self))
                         ^^^^^^^^^^^^^^^^^^^^^^^^^^^^^^^^
  File "C:\Users\Simon\AppData\Roaming\Python\Python311\site-packages\django\db\models\query.py", line 91, in __iter__
    results = compiler.execute_sql(
              ^^^^^^^^^^^^^^^^^^^^^
  File "C:\Users\Simon\AppData\Roaming\Python\Python311\site-packages\django\db\models\sql\compiler.py", line 1562, in execute_sql
    cursor.execute(sql, params)
  File "C:\Users\Simon\AppData\Roaming\Python\Python311\site-packages\django\db\backends\utils.py", line 102, in execute
    return super().execute(sql, params)
           ^^^^^^^^^^^^^^^^^^^^^^^^^^^^
  File "C:\Users\Simon\AppData\Roaming\Python\Python311\site-packages\django\db\backends\utils.py", line 67, in execute
    return self._execute_with_wrappers(
           ^^^^^^^^^^^^^^^^^^^^^^^^^^^^
  File "C:\Users\Simon\AppData\Roaming\Python\Python311\site-packages\django\db\backends\utils.py", line 80, in _execute_with_wrappers
    return executor(sql, params, many, context)
           ^^^^^^^^^^^^^^^^^^^^^^^^^^^^^^^^^^^^
  File "C:\Users\Simon\AppData\Roaming\Python\Python311\site-packages\django\db\backends\utils.py", line 84, in _execute
    with self.db.wrap_database_errors:
  File "C:\Users\Simon\AppData\Roaming\Python\Python311\site-packages\django\db\utils.py", line 91, in __exit__
    raise dj_exc_value.with_traceback(traceback) from exc_value
  File "C:\Users\Simon\AppData\Roaming\Python\Python311\site-packages\django\db\backends\utils.py", line 89, in _execute
    return self.cursor.execute(sql, params)
           ^^^^^^^^^^^^^^^^^^^^^^^^^^^^^^^^
  File "C:\Users\Simon\AppData\Roaming\Python\Python311\site-packages\django\db\backends\sqlite3\base.py", line 328, in execute
    return super().execute(query, params)
           ^^^^^^^^^^^^^^^^^^^^^^^^^^^^^^
django.db.utils.OperationalError: no such column: academia_app_baseuser.role
INFO || 11-Jun-24 22:10:37 || C:\Users\Simon\proacted\AIacademia\academia_app\urls.py changed, reloading.
WARNING || 11-Jun-24 22:22:31 || Not Found: /ws/academia_app/
ERROR || 11-Jun-24 22:27:02 || Internal Server Error: /auth/dashboard/
Traceback (most recent call last):
  File "C:\Users\Simon\AppData\Roaming\Python\Python311\site-packages\django\core\handlers\exception.py", line 55, in inner
    response = get_response(request)
               ^^^^^^^^^^^^^^^^^^^^^
  File "C:\Users\Simon\AppData\Roaming\Python\Python311\site-packages\django\core\handlers\base.py", line 197, in _get_response
    response = wrapped_callback(request, *callback_args, **callback_kwargs)
               ^^^^^^^^^^^^^^^^^^^^^^^^^^^^^^^^^^^^^^^^^^^^^^^^^^^^^^^^^^^^
  File "C:\Users\Simon\AppData\Roaming\Python\Python311\site-packages\django\contrib\auth\decorators.py", line 23, in _wrapper_view
    return view_func(request, *args, **kwargs)
           ^^^^^^^^^^^^^^^^^^^^^^^^^^^^^^^^^^^
  File "C:\Users\Simon\proacted\AIacademia\academia_app\views.py", line 229, in dashboard
    total_staff = AdminUser.objects.count()
                  ^^^^^^^^^
NameError: name 'AdminUser' is not defined
ERROR || 11-Jun-24 22:27:13 || Internal Server Error: /auth/dashboard/
Traceback (most recent call last):
  File "C:\Users\Simon\AppData\Roaming\Python\Python311\site-packages\django\core\handlers\exception.py", line 55, in inner
    response = get_response(request)
               ^^^^^^^^^^^^^^^^^^^^^
  File "C:\Users\Simon\AppData\Roaming\Python\Python311\site-packages\django\core\handlers\base.py", line 197, in _get_response
    response = wrapped_callback(request, *callback_args, **callback_kwargs)
               ^^^^^^^^^^^^^^^^^^^^^^^^^^^^^^^^^^^^^^^^^^^^^^^^^^^^^^^^^^^^
  File "C:\Users\Simon\AppData\Roaming\Python\Python311\site-packages\django\contrib\auth\decorators.py", line 23, in _wrapper_view
    return view_func(request, *args, **kwargs)
           ^^^^^^^^^^^^^^^^^^^^^^^^^^^^^^^^^^^
  File "C:\Users\Simon\proacted\AIacademia\academia_app\views.py", line 229, in dashboard
    total_staff = AdminUser.objects.count()
                  ^^^^^^^^^
NameError: name 'AdminUser' is not defined
ERROR || 11-Jun-24 22:27:30 || Internal Server Error: /auth/dashboard/
Traceback (most recent call last):
  File "C:\Users\Simon\AppData\Roaming\Python\Python311\site-packages\django\core\handlers\exception.py", line 55, in inner
    response = get_response(request)
               ^^^^^^^^^^^^^^^^^^^^^
  File "C:\Users\Simon\AppData\Roaming\Python\Python311\site-packages\django\core\handlers\base.py", line 197, in _get_response
    response = wrapped_callback(request, *callback_args, **callback_kwargs)
               ^^^^^^^^^^^^^^^^^^^^^^^^^^^^^^^^^^^^^^^^^^^^^^^^^^^^^^^^^^^^
  File "C:\Users\Simon\AppData\Roaming\Python\Python311\site-packages\django\contrib\auth\decorators.py", line 23, in _wrapper_view
    return view_func(request, *args, **kwargs)
           ^^^^^^^^^^^^^^^^^^^^^^^^^^^^^^^^^^^
  File "C:\Users\Simon\proacted\AIacademia\academia_app\views.py", line 229, in dashboard
    total_staff = AdminUser.objects.count()
                  ^^^^^^^^^
NameError: name 'AdminUser' is not defined
INFO || 11-Jun-24 22:30:36 || C:\Users\Simon\proacted\AIacademia\academia_app\views.py changed, reloading.
INFO || 11-Jun-24 22:31:31 || C:\Users\Simon\proacted\AIacademia\academia_app\views.py changed, reloading.
INFO || 11-Jun-24 22:31:55 || C:\Users\Simon\proacted\AIacademia\academia_app\urls.py changed, reloading.
INFO || 11-Jun-24 22:32:20 || C:\Users\Simon\proacted\AIacademia\academia_app\urls.py changed, reloading.
INFO || 11-Jun-24 22:37:05 || C:\Users\Simon\proacted\AIacademia\academia_app\views.py changed, reloading.
ERROR || 11-Jun-24 22:44:37 || Internal Server Error: /admin/academia_app/studentuserproxy/add/
Traceback (most recent call last):
  File "C:\Users\Simon\AppData\Roaming\Python\Python311\site-packages\django\db\backends\utils.py", line 89, in _execute
    return self.cursor.execute(sql, params)
           ^^^^^^^^^^^^^^^^^^^^^^^^^^^^^^^^
  File "C:\Users\Simon\AppData\Roaming\Python\Python311\site-packages\django\db\backends\sqlite3\base.py", line 328, in execute
    return super().execute(query, params)
           ^^^^^^^^^^^^^^^^^^^^^^^^^^^^^^
sqlite3.IntegrityError: NOT NULL constraint failed: academia_app_studentuser.course_id

The above exception was the direct cause of the following exception:

Traceback (most recent call last):
  File "C:\Users\Simon\AppData\Roaming\Python\Python311\site-packages\django\core\handlers\exception.py", line 55, in inner
    response = get_response(request)
               ^^^^^^^^^^^^^^^^^^^^^
  File "C:\Users\Simon\AppData\Roaming\Python\Python311\site-packages\django\core\handlers\base.py", line 197, in _get_response
    response = wrapped_callback(request, *callback_args, **callback_kwargs)
               ^^^^^^^^^^^^^^^^^^^^^^^^^^^^^^^^^^^^^^^^^^^^^^^^^^^^^^^^^^^^
  File "C:\Users\Simon\AppData\Roaming\Python\Python311\site-packages\django\contrib\admin\options.py", line 688, in wrapper
    return self.admin_site.admin_view(view)(*args, **kwargs)
           ^^^^^^^^^^^^^^^^^^^^^^^^^^^^^^^^^^^^^^^^^^^^^^^^^
  File "C:\Users\Simon\AppData\Roaming\Python\Python311\site-packages\django\utils\decorators.py", line 134, in _wrapper_view
    response = view_func(request, *args, **kwargs)
               ^^^^^^^^^^^^^^^^^^^^^^^^^^^^^^^^^^^
  File "C:\Users\Simon\AppData\Roaming\Python\Python311\site-packages\django\views\decorators\cache.py", line 62, in _wrapper_view_func
    response = view_func(request, *args, **kwargs)
               ^^^^^^^^^^^^^^^^^^^^^^^^^^^^^^^^^^^
  File "C:\Users\Simon\AppData\Roaming\Python\Python311\site-packages\django\contrib\admin\sites.py", line 242, in inner
    return view(request, *args, **kwargs)
           ^^^^^^^^^^^^^^^^^^^^^^^^^^^^^^
  File "C:\Users\Simon\AppData\Roaming\Python\Python311\site-packages\django\utils\decorators.py", line 46, in _wrapper
    return bound_method(*args, **kwargs)
           ^^^^^^^^^^^^^^^^^^^^^^^^^^^^^
  File "C:\Users\Simon\AppData\Roaming\Python\Python311\site-packages\django\views\decorators\debug.py", line 92, in sensitive_post_parameters_wrapper
    return view(request, *args, **kwargs)
           ^^^^^^^^^^^^^^^^^^^^^^^^^^^^^^
  File "C:\Users\Simon\AppData\Roaming\Python\Python311\site-packages\django\utils\decorators.py", line 46, in _wrapper
    return bound_method(*args, **kwargs)
           ^^^^^^^^^^^^^^^^^^^^^^^^^^^^^
  File "C:\Users\Simon\AppData\Roaming\Python\Python311\site-packages\django\utils\decorators.py", line 134, in _wrapper_view
    response = view_func(request, *args, **kwargs)
               ^^^^^^^^^^^^^^^^^^^^^^^^^^^^^^^^^^^
  File "C:\Users\Simon\AppData\Roaming\Python\Python311\site-packages\django\contrib\auth\admin.py", line 119, in add_view
    return self._add_view(request, form_url, extra_context)
           ^^^^^^^^^^^^^^^^^^^^^^^^^^^^^^^^^^^^^^^^^^^^^^^^
  File "C:\Users\Simon\AppData\Roaming\Python\Python311\site-packages\django\contrib\auth\admin.py", line 147, in _add_view
    return super().add_view(request, form_url, extra_context)
           ^^^^^^^^^^^^^^^^^^^^^^^^^^^^^^^^^^^^^^^^^^^^^^^^^^
  File "C:\Users\Simon\AppData\Roaming\Python\Python311\site-packages\django\contrib\admin\options.py", line 1886, in add_view
    return self.changeform_view(request, None, form_url, extra_context)
           ^^^^^^^^^^^^^^^^^^^^^^^^^^^^^^^^^^^^^^^^^^^^^^^^^^^^^^^^^^^^
  File "C:\Users\Simon\AppData\Roaming\Python\Python311\site-packages\django\utils\decorators.py", line 46, in _wrapper
    return bound_method(*args, **kwargs)
           ^^^^^^^^^^^^^^^^^^^^^^^^^^^^^
  File "C:\Users\Simon\AppData\Roaming\Python\Python311\site-packages\django\utils\decorators.py", line 134, in _wrapper_view
    response = view_func(request, *args, **kwargs)
               ^^^^^^^^^^^^^^^^^^^^^^^^^^^^^^^^^^^
  File "C:\Users\Simon\AppData\Roaming\Python\Python311\site-packages\django\contrib\admin\options.py", line 1747, in changeform_view
    return self._changeform_view(request, object_id, form_url, extra_context)
           ^^^^^^^^^^^^^^^^^^^^^^^^^^^^^^^^^^^^^^^^^^^^^^^^^^^^^^^^^^^^^^^^^^
  File "C:\Users\Simon\AppData\Roaming\Python\Python311\site-packages\django\contrib\admin\options.py", line 1798, in _changeform_view
    self.save_model(request, new_object, form, not add)
  File "C:\Users\Simon\proacted\AIacademia\academia_app\admin.py", line 37, in save_model
    super().save_model(request, obj, form, change)
  File "C:\Users\Simon\AppData\Roaming\Python\Python311\site-packages\django\contrib\admin\options.py", line 1227, in save_model
    obj.save()
  File "C:\Users\Simon\AppData\Roaming\Python\Python311\site-packages\django\contrib\auth\base_user.py", line 76, in save
    super().save(*args, **kwargs)
  File "C:\Users\Simon\AppData\Roaming\Python\Python311\site-packages\django\db\models\base.py", line 814, in save
    self.save_base(
  File "C:\Users\Simon\AppData\Roaming\Python\Python311\site-packages\django\db\models\base.py", line 877, in save_base
    updated = self._save_table(
              ^^^^^^^^^^^^^^^^^
  File "C:\Users\Simon\AppData\Roaming\Python\Python311\site-packages\django\db\models\base.py", line 1020, in _save_table
    results = self._do_insert(
              ^^^^^^^^^^^^^^^^
  File "C:\Users\Simon\AppData\Roaming\Python\Python311\site-packages\django\db\models\base.py", line 1061, in _do_insert
    return manager._insert(
           ^^^^^^^^^^^^^^^^
  File "C:\Users\Simon\AppData\Roaming\Python\Python311\site-packages\django\db\models\manager.py", line 87, in manager_method
    return getattr(self.get_queryset(), name)(*args, **kwargs)
           ^^^^^^^^^^^^^^^^^^^^^^^^^^^^^^^^^^^^^^^^^^^^^^^^^^^
  File "C:\Users\Simon\AppData\Roaming\Python\Python311\site-packages\django\db\models\query.py", line 1805, in _insert
    return query.get_compiler(using=using).execute_sql(returning_fields)
           ^^^^^^^^^^^^^^^^^^^^^^^^^^^^^^^^^^^^^^^^^^^^^^^^^^^^^^^^^^^^^
  File "C:\Users\Simon\AppData\Roaming\Python\Python311\site-packages\django\db\models\sql\compiler.py", line 1822, in execute_sql
    cursor.execute(sql, params)
  File "C:\Users\Simon\AppData\Roaming\Python\Python311\site-packages\django\db\backends\utils.py", line 102, in execute
    return super().execute(sql, params)
           ^^^^^^^^^^^^^^^^^^^^^^^^^^^^
  File "C:\Users\Simon\AppData\Roaming\Python\Python311\site-packages\django\db\backends\utils.py", line 67, in execute
    return self._execute_with_wrappers(
           ^^^^^^^^^^^^^^^^^^^^^^^^^^^^
  File "C:\Users\Simon\AppData\Roaming\Python\Python311\site-packages\django\db\backends\utils.py", line 80, in _execute_with_wrappers
    return executor(sql, params, many, context)
           ^^^^^^^^^^^^^^^^^^^^^^^^^^^^^^^^^^^^
  File "C:\Users\Simon\AppData\Roaming\Python\Python311\site-packages\django\db\backends\utils.py", line 84, in _execute
    with self.db.wrap_database_errors:
  File "C:\Users\Simon\AppData\Roaming\Python\Python311\site-packages\django\db\utils.py", line 91, in __exit__
    raise dj_exc_value.with_traceback(traceback) from exc_value
  File "C:\Users\Simon\AppData\Roaming\Python\Python311\site-packages\django\db\backends\utils.py", line 89, in _execute
    return self.cursor.execute(sql, params)
           ^^^^^^^^^^^^^^^^^^^^^^^^^^^^^^^^
  File "C:\Users\Simon\AppData\Roaming\Python\Python311\site-packages\django\db\backends\sqlite3\base.py", line 328, in execute
    return super().execute(query, params)
           ^^^^^^^^^^^^^^^^^^^^^^^^^^^^^^
django.db.utils.IntegrityError: NOT NULL constraint failed: academia_app_studentuser.course_id
